Workbook

Sheet Leads
A1: Lead Tracker — 15% commission log | I1: Unpaid commission: | K1: =SUM(N3:N502) | L1: Grey columns are automatic — don't type in them.
A2: Date Received | B2: Name | C2: Company | D2: Source Code | E2: Channel | F2: Service Enquired | G2: Deal Value (update to actual on invoice) | H2: Status | I2: Invoice Date | J2: Commission Due | K2: Commission Paid | L2: Notes | M2: Won? (auto) | N2: Commission Outstanding (auto)
J3: =IF($G8="","",$G8*0.15) | M3: =IF($A8="","",IF(OR($H8="delivered",$H8="invoiced",$H8="paid"),1,0)) | N3: =IF($A8="","",IF(AND($M8=1,$J8<>""),$J8-IF($K8="",0,$K8),""))
J4: =IF($G9="","",$G9*0.15) | M4: =IF($A9="","",IF(OR($H9="delivered",$H9="invoiced",$H9="paid"),1,0)) | N4: =IF($A9="","",IF(AND($M9=1,$J9<>""),$J9-IF($K9="",0,$K9),""))
J5: =IF($G10="","",$G10*0.15) | M5: =IF($A10="","",IF(OR($H10="delivered",$H10="invoiced",$H10="paid"),1,0)) | N5: =IF($A10="","",IF(AND($M10=1,$J10<>""),$J10-IF($K10="",0,$K10),""))
J6: =IF($G11="","",$G11*0.15) | M6: =IF($A11="","",IF(OR($H11="delivered",$H11="invoiced",$H11="paid"),1,0)) | N6: =IF($A11="","",IF(AND($M11=1,$J11<>""),$J11-IF($K11="",0,$K11),""))
J7: =IF($G12="","",$G12*0.15) | M7: =IF($A12="","",IF(OR($H12="delivered",$H12="invoiced",$H12="paid"),1,0)) | N7: =IF($A12="","",IF(AND($M12=1,$J12<>""),$J12-IF($K12="",0,$K12),""))
J8: =IF($G13="","",$G13*0.15) | M8: =IF($A13="","",IF(OR($H13="delivered",$H13="invoiced",$H13="paid"),1,0)) | N8: =IF($A13="","",IF(AND($M13=1,$J13<>""),$J13-IF($K13="",0,$K13),""))
J9: =IF($G14="","",$G14*0.15) | M9: =IF($A14="","",IF(OR($H14="delivered",$H14="invoiced",$H14="paid"),1,0)) | N9: =IF($A14="","",IF(AND($M14=1,$J14<>""),$J14-IF($K14="",0,$K14),""))
J10: =IF($G15="","",$G15*0.15) | M10: =IF($A15="","",IF(OR($H15="delivered",$H15="invoiced",$H15="paid"),1,0)) | N10: =IF($A15="","",IF(AND($M15=1,$J15<>""),$J15-IF($K15="",0,$K15),""))
J11: =IF($G16="","",$G16*0.15) | M11: =IF($A16="","",IF(OR($H16="delivered",$H16="invoiced",$H16="paid"),1,0)) | N11: =IF($A16="","",IF(AND($M16=1,$J16<>""),$J16-IF($K16="",0,$K16),""))
J12: =IF($G17="","",$G17*0.15) | M12: =IF($A17="","",IF(OR($H17="delivered",$H17="invoiced",$H17="paid"),1,0)) | N12: =IF($A17="","",IF(AND($M17=1,$J17<>""),$J17-IF($K17="",0,$K17),""))
J13: =IF($G18="","",$G18*0.15) | M13: =IF($A18="","",IF(OR($H18="delivered",$H18="invoiced",$H18="paid"),1,0)) | N13: =IF($A18="","",IF(AND($M18=1,$J18<>""),$J18-IF($K18="",0,$K18),""))
J14: =IF($G19="","",$G19*0.15) | M14: =IF($A19="","",IF(OR($H19="delivered",$H19="invoiced",$H19="paid"),1,0)) | N14: =IF($A19="","",IF(AND($M19=1,$J19<>""),$J19-IF($K19="",0,$K19),""))
... J497: =IF($G502="","",$G502*0.15) | M497: =IF($A502="","",IF(OR($H502="delivered",$H502="invoiced",$H502="paid"),1,0)) | N497: =IF($A502="","",IF(AND($M502=1,$J502<>""),$J502-IF($K502="",0,$K502),""))

Sheet Monthly Rollup
A1: Monthly Rollup
A3: Overall — all time
A4: Total Leads | B4: Won Deals | C4: Conversion | D4: Revenue (won) | E4: Commission Due | F4: Commission Paid | G4: Unpaid Commission
A5: =COUNT(Leads!$A$3:$A$502) | B5: =SUM(Leads!$M$3:$M$502) | C5: =IF(A5=0,"",B5/A5) | D5: =SUMIFS(Leads!$G$3:$G$502,Leads!$M$3:$M$502,1) | E5: =SUMIFS(Leads!$J$3:$J$502,Leads!$M$3:$M$502,1) | F5: =SUM(Leads!$K$3:$K$502) | G5: =SUM(Leads!$N$3:$N$502)
A7: By month
A8: Start month: | B8: 46204 | C8: ← change to your first month (yellow cells are the only inputs on this tab)
A9: Month | B9: Leads | C9: Won | D9: Lost | E9: Conversion % | F9: Revenue | G9: Commission Owed
A10: =$B$8 | B10: =COUNTIFS(Leads!$A$3:$A$502,">="&$A10,Leads!$A$3:$A$502,"<"&EDATE($A10,1)) | C10: =COUNTIFS(Leads!$A$3:$A$502,">="&$A10,Leads!$A$3:$A$502,"<"&EDATE($A10,1),Leads!$M$3:$M$502,1) | D10: =COUNTIFS(Leads!$A$3:$A$502,">="&$A10,Leads!$A$3:$A$502,"<"&EDATE($A10,1),Leads!$H$3:$H$502,"lost") | E10: =IF(B10=0,"",C10/B10) | F10: =SUMIFS(Leads!$G$3:$G$502,Leads!$A$3:$A$502,">="&$A10,Leads!$A$3:$A$502,"<"&EDATE($A10,1),Leads!$M$3:$M$502,1) | G10: =SUMIFS(Leads!$J$3:$J$502,Leads!$A$3:$A$502,">="&$A10,Leads!$A$3:$A$502,"<"&EDATE($A10,1),Leads!$M$3:$M$502,1)
A11: =EDATE(A10,1) | B11: =COUNTIFS(Leads!$A$3:$A$502,">="&$A11,Leads!$A$3:$A$502,"<"&EDATE($A11,1)) | C11: =COUNTIFS(Leads!$A$3:$A$502,">="&$A11,Leads!$A$3:$A$502,"<"&EDATE($A11,1),Leads!$M$3:$M$502,1) | D11: =COUNTIFS(Leads!$A$3:$A$502,">="&$A11,Leads!$A$3:$A$502,"<"&EDATE($A11,1),Leads!$H$3:$H$502,"lost") | E11: =IF(B11=0,"",C11/B11) | F11: =SUMIFS(Leads!$G$3:$G$502,Leads!$A$3:$A$502,">="&$A11,Leads!$A$3:$A$502,"<"&EDATE($A11,1),Leads!$M$3:$M$502,1) | G11: =SUMIFS(Leads!$J$3:$J$502,Leads!$A$3:$A$502,">="&$A11,Leads!$A$3:$A$502,"<"&EDATE($A11,1),Leads!$M$3:$M$502,1)
A12: =EDATE(A11,1) | B12: =COUNTIFS(Leads!$A$3:$A$502,">="&$A12,Leads!$A$3:$A$502,"<"&EDATE($A12,1)) | C12: =COUNTIFS(Leads!$A$3:$A$502,">="&$A12,Leads!$A$3:$A$502,"<"&EDATE($A12,1),Leads!$M$3:$M$502,1) | D12: =COUNTIFS(Leads!$A$3:$A$502,">="&$A12,Leads!$A$3:$A$502,"<"&EDATE($A12,1),Leads!$H$3:$H$502,"lost") | E12: =IF(B12=0,"",C12/B12) | F12: =SUMIFS(Leads!$G$3:$G$502,Leads!$A$3:$A$502,">="&$A12,Leads!$A$3:$A$502,"<"&EDATE($A12,1),Leads!$M$3:$M$502,1) | G12: =SUMIFS(Leads!$J$3:$J$502,Leads!$A$3:$A$502,">="&$A12,Leads!$A$3:$A$502,"<"&EDATE($A12,1),Leads!$M$3:$M$502,1)
A13: =EDATE(A12,1) | B13: =COUNTIFS(Leads!$A$3:$A$502,">="&$A13,Leads!$A$3:$A$502,"<"&EDATE($A13,1)) | C13: =COUNTIFS(Leads!$A$3:$A$502,">="&$A13,Leads!$A$3:$A$502,"<"&EDATE($A13,1),Leads!$M$3:$M$502,1) | D13: =COUNTIFS(Leads!$A$3:$A$502,">="&$A13,Leads!$A$3:$A$502,"<"&EDATE($A13,1),Leads!$H$3:$H$502,"lost") | E13: =IF(B13=0,"",C13/B13) | F13: =SUMIFS(Leads!$G$3:$G$502,Leads!$A$3:$A$502,">="&$A13,Leads!$A$3:$A$502,"<"&EDATE($A13,1),Leads!$M$3:$M$502,1) | G13: =SUMIFS(Leads!$J$3:$J$502,Leads!$A$3:$A$502,">="&$A13,Leads!$A$3:$A$502,"<"&EDATE($A13,1),Leads!$M$3:$M$502,1)
A14: =EDATE(A13,1) | B14: =COUNTIFS(Leads!$A$3:$A$502,">="&$A14,Leads!$A$3:$A$502,"<"&EDATE($A14,1)) | C14: =COUNTIFS(Leads!$A$3:$A$502,">="&$A14,Leads!$A$3:$A$502,"<"&EDATE($A14,1),Leads!$M$3:$M$502,1) | D14: =COUNTIFS(Leads!$A$3:$A$502,">="&$A14,Leads!$A$3:$A$502,"<"&EDATE($A14,1),Leads!$H$3:$H$502,"lost") | E14: =IF(B14=0,"",C14/B14) | F14: =SUMIFS(Leads!$G$3:$G$502,Leads!$A$3:$A$502,">="&$A14,Leads!$A$3:$A$502,"<"&EDATE($A14,1),Leads!$M$3:$M$502,1) | G14: =SUMIFS(Leads!$J$3:$J$502,Leads!$A$3:$A$502,">="&$A14,Leads!$A$3:$A$502,"<"&EDATE($A14,1),Leads!$M$3:$M$502,1)
A15: =EDATE(A14,1) | B15: =COUNTIFS(Leads!$A$3:$A$502,">="&$A15,Leads!$A$3:$A$502,"<"&EDATE($A15,1)) | C15: =COUNTIFS(Leads!$A$3:$A$502,">="&$A15,Leads!$A$3:$A$502,"<"&EDATE($A15,1),Leads!$M$3:$M$502,1) | D15: =COUNTIFS(Leads!$A$3:$A$502,">="&$A15,Leads!$A$3:$A$502,"<"&EDATE($A15,1),Leads!$H$3:$H$502,"lost") | E15: =IF(B15=0,"",C15/B15) | F15: =SUMIFS(Leads!$G$3:$G$502,Leads!$A$3:$A$502,">="&$A15,Leads!$A$3:$A$502,"<"&EDATE($A15,1),Leads!$M$3:$M$502,1) | G15: =SUMIFS(Leads!$J$3:$J$502,Leads!$A$3:$A$502,">="&$A15,Leads!$A$3:$A$502,"<"&EDATE($A15,1),Leads!$M$3:$M$502,1)
A16: =EDATE(A15,1) | B16: =COUNTIFS(Leads!$A$3:$A$502,">="&$A16,Leads!$A$3:$A$502,"<"&EDATE($A16,1)) | C16: =COUNTIFS(Leads!$A$3:$A$502,">="&$A16,Leads!$A$3:$A$502,"<"&EDATE($A16,1),Leads!$M$3:$M$502,1) | D16: =COUNTIFS(Leads!$A$3:$A$502,">="&$A16,Leads!$A$3:$A$502,"<"&EDATE($A16,1),Leads!$H$3:$H$502,"lost") | E16: =IF(B16=0,"",C16/B16) | F16: =SUMIFS(Leads!$G$3:$G$502,Leads!$A$3:$A$502,">="&$A16,Leads!$A$3:$A$502,"<"&EDATE($A16,1),Leads!$M$3:$M$502,1) | G16: =SUMIFS(Leads!$J$3:$J$502,Leads!$A$3:$A$502,">="&$A16,Leads!$A$3:$A$502,"<"&EDATE($A16,1),Leads!$M$3:$M$502,1)
A17: =EDATE(A16,1) | B17: =COUNTIFS(Leads!$A$3:$A$502,">="&$A17,Leads!$A$3:$A$502,"<"&EDATE($A17,1)) | C17: =COUNTIFS(Leads!$A$3:$A$502,">="&$A17,Leads!$A$3:$A$502,"<"&EDATE($A17,1),Leads!$M$3:$M$502,1) | D17: =COUNTIFS(Leads!$A$3:$A$502,">="&$A17,Leads!$A$3:$A$502,"<"&EDATE($A17,1),Leads!$H$3:$H$502,"lost") | E17: =IF(B17=0,"",C17/B17) | F17: =SUMIFS(Leads!$G$3:$G$502,Leads!$A$3:$A$502,">="&$A17,Leads!$A$3:$A$502,"<"&EDATE($A17,1),Leads!$M$3:$M$502,1) | G17: =SUMIFS(Leads!$J$3:$J$502,Leads!$A$3:$A$502,">="&$A17,Leads!$A$3:$A$502,"<"&EDATE($A17,1),Leads!$M$3:$M$502,1)
A18: =EDATE(A17,1) | B18: =COUNTIFS(Leads!$A$3:$A$502,">="&$A18,Leads!$A$3:$A$502,"<"&EDATE($A18,1)) | C18: =COUNTIFS(Leads!$A$3:$A$502,">="&$A18,Leads!$A$3:$A$502,"<"&EDATE($A18,1),Leads!$M$3:$M$502,1) | D18: =COUNTIFS(Leads!$A$3:$A$502,">="&$A18,Leads!$A$3:$A$502,"<"&EDATE($A18,1),Leads!$H$3:$H$502,"lost") | E18: =IF(B18=0,"",C18/B18) | F18: =SUMIFS(Leads!$G$3:$G$502,Leads!$A$3:$A$502,">="&$A18,Leads!$A$3:$A$502,"<"&EDATE($A18,1),Leads!$M$3:$M$502,1) | G18: =SUMIFS(Leads!$J$3:$J$502,Leads!$A$3:$A$502,">="&$A18,Leads!$A$3:$A$502,"<"&EDATE($A18,1),Leads!$M$3:$M$502,1)
A19: =EDATE(A18,1) | B19: =COUNTIFS(Leads!$A$3:$A$502,">="&$A19,Leads!$A$3:$A$502,"<"&EDATE($A19,1)) | C19: =COUNTIFS(Leads!$A$3:$A$502,">="&$A19,Leads!$A$3:$A$502,"<"&EDATE($A19,1),Leads!$M$3:$M$502,1) | D19: =COUNTIFS(Leads!$A$3:$A$502,">="&$A19,Leads!$A$3:$A$502,"<"&EDATE($A19,1),Leads!$H$3:$H$502,"lost") | E19: =IF(B19=0,"",C19/B19) | F19: =SUMIFS(Leads!$G$3:$G$502,Leads!$A$3:$A$502,">="&$A19,Leads!$A$3:$A$502,"<"&EDATE($A19,1),Leads!$M$3:$M$502,1) | G19: =SUMIFS(Leads!$J$3:$J$502,Leads!$A$3:$A$502,">="&$A19,Leads!$A$3:$A$502,"<"&EDATE($A19,1),Leads!$M$3:$M$502,1)
A20: =EDATE(A19,1) | B20: =COUNTIFS(Leads!$A$3:$A$502,">="&$A20,Leads!$A$3:$A$502,"<"&EDATE($A20,1)) | C20: =COUNTIFS(Leads!$A$3:$A$502,">="&$A20,Leads!$A$3:$A$502,"<"&EDATE($A20,1),Leads!$M$3:$M$502,1) | D20: =COUNTIFS(Leads!$A$3:$A$502,">="&$A20,Leads!$A$3:$A$502,"<"&EDATE($A20,1),Leads!$H$3:$H$502,"lost") | E20: =IF(B20=0,"",C20/B20) | F20: =SUMIFS(Leads!$G$3:$G$502,Leads!$A$3:$A$502,">="&$A20,Leads!$A$3:$A$502,"<"&EDATE($A20,1),Leads!$M$3:$M$502,1) | G20: =SUMIFS(Leads!$J$3:$J$502,Leads!$A$3:$A$502,">="&$A20,Leads!$A$3:$A$502,"<"&EDATE($A20,1),Leads!$M$3:$M$502,1)
A21: =EDATE(A20,1) | B21: =COUNTIFS(Leads!$A$3:$A$502,">="&$A21,Leads!$A$3:$A$502,"<"&EDATE($A21,1)) | C21: =COUNTIFS(Leads!$A$3:$A$502,">="&$A21,Leads!$A$3:$A$502,"<"&EDATE($A21,1),Leads!$M$3:$M$502,1) | D21: =COUNTIFS(Leads!$A$3:$A$502,">="&$A21,Leads!$A$3:$A$502,"<"&EDATE($A21,1),Leads!$H$3:$H$502,"lost") | E21: =IF(B21=0,"",C21/B21) | F21: =SUMIFS(Leads!$G$3:$G$502,Leads!$A$3:$A$502,">="&$A21,Leads!$A$3:$A$502,"<"&EDATE($A21,1),Leads!$M$3:$M$502,1) | G21: =SUMIFS(Leads!$J$3:$J$502,Leads!$A$3:$A$502,">="&$A21,Leads!$A$3:$A$502,"<"&EDATE($A21,1),Leads!$M$3:$M$502,1)
A22: =EDATE(A21,1) | B22: =COUNTIFS(Leads!$A$3:$A$502,">="&$A22,Leads!$A$3:$A$502,"<"&EDATE($A22,1)) | C22: =COUNTIFS(Leads!$A$3:$A$502,">="&$A22,Leads!$A$3:$A$502,"<"&EDATE($A22,1),Leads!$M$3:$M$502,1) | D22: =COUNTIFS(Leads!$A$3:$A$502,">="&$A22,Leads!$A$3:$A$502,"<"&EDATE($A22,1),Leads!$H$3:$H$502,"lost") | E22: =IF(B22=0,"",C22/B22) | F22: =SUMIFS(Leads!$G$3:$G$502,Leads!$A$3:$A$502,">="&$A22,Leads!$A$3:$A$502,"<"&EDATE($A22,1),Leads!$M$3:$M$502,1) | G22: =SUMIFS(Leads!$J$3:$J$502,Leads!$A$3:$A$502,">="&$A22,Leads!$A$3:$A$502,"<"&EDATE($A22,1),Leads!$M$3:$M$502,1)
... A33: =EDATE(A32,1) | B33: =COUNTIFS(Leads!$A$3:$A$502,">="&$A33,Leads!$A$3:$A$502,"<"&EDATE($A33,1)) | C33: =COUNTIFS(Leads!$A$3:$A$502,">="&$A33,Leads!$A$3:$A$502,"<"&EDATE($A33,1),Leads!$M$3:$M$502,1) | D33: =COUNTIFS(Leads!$A$3:$A$502,">="&$A33,Leads!$A$3:$A$502,"<"&EDATE($A33,1),Leads!$H$3:$H$502,"lost") | E33: =IF(B33=0,"",C33/B33) | F33: =SUMIFS(Leads!$G$3:$G$502,Leads!$A$3:$A$502,">="&$A33,Leads!$A$3:$A$502,"<"&EDATE($A33,1),Leads!$M$3:$M$502,1) | G33: =SUMIFS(Leads!$J$3:$J$502,Leads!$A$3:$A$502,">="&$A33,Leads!$A$3:$A$502,"<"&EDATE($A33,1),Leads!$M$3:$M$502,1)
A34: All months | B34: =SUM(B10:B33) | C34: =SUM(C10:C33) | D34: =SUM(D10:D33) | E34: =IF(B34=0,"",C34/B34) | F34: =SUM(F10:F33) | G34: =SUM(G10:G33)
A37: By source code — selected month
A38: Report month: | B38: 46266
A39: Source | B39: Leads | C39: Won | D39: Conversion % | E39: Revenue | F39: Commission Owed
A40: WEB-GC | B40: =COUNTIFS(Leads!$A$3:$A$502,">="&$B$38,Leads!$A$3:$A$502,"<"&EDATE($B$38,1),Leads!$D$3:$D$502,$A40) | C40: =COUNTIFS(Leads!$A$3:$A$502,">="&$B$38,Leads!$A$3:$A$502,"<"&EDATE($B$38,1),Leads!$D$3:$D$502,$A40,Leads!$M$3:$M$502,1) | D40: =IF(B40=0,"",C40/B40) | E40: =SUMIFS(Leads!$G$3:$G$502,Leads!$A$3:$A$502,">="&$B$38,Leads!$A$3:$A$502,"<"&EDATE($B$38,1),Leads!$D$3:$D$502,$A40,Leads!$M$3:$M$502,1) | F40: =SUMIFS(Leads!$J$3:$J$502,Leads!$A$3:$A$502,">="&$B$38,Leads!$A$3:$A$502,"<"&EDATE($B$38,1),Leads!$D$3:$D$502,$A40,Leads!$M$3:$M$502,1)
A41: WEB-OSHC | B41: =COUNTIFS(Leads!$A$3:$A$502,">="&$B$38,Leads!$A$3:$A$502,"<"&EDATE($B$38,1),Leads!$D$3:$D$502,$A41) | C41: =COUNTIFS(Leads!$A$3:$A$502,">="&$B$38,Leads!$A$3:$A$502,"<"&EDATE($B$38,1),Leads!$D$3:$D$502,$A41,Leads!$M$3:$M$502,1) | D41: =IF(B41=0,"",C41/B41) | E41: =SUMIFS(Leads!$G$3:$G$502,Leads!$A$3:$A$502,">="&$B$38,Leads!$A$3:$A$502,"<"&EDATE($B$38,1),Leads!$D$3:$D$502,$A41,Leads!$M$3:$M$502,1) | F41: =SUMIFS(Leads!$J$3:$J$502,Leads!$A$3:$A$502,">="&$B$38,Leads!$A$3:$A$502,"<"&EDATE($B$38,1),Leads!$D$3:$D$502,$A41,Leads!$M$3:$M$502,1)
A42: WEB-HRD | B42: =COUNTIFS(Leads!$A$3:$A$502,">="&$B$38,Leads!$A$3:$A$502,"<"&EDATE($B$38,1),Leads!$D$3:$D$502,$A42) | C42: =COUNTIFS(Leads!$A$3:$A$502,">="&$B$38,Leads!$A$3:$A$502,"<"&EDATE($B$38,1),Leads!$D$3:$D$502,$A42,Leads!$M$3:$M$502,1) | D42: =IF(B42=0,"",C42/B42) | E42: =SUMIFS(Leads!$G$3:$G$502,Leads!$A$3:$A$502,">="&$B$38,Leads!$A$3:$A$502,"<"&EDATE($B$38,1),Leads!$D$3:$D$502,$A42,Leads!$M$3:$M$502,1) | F42: =SUMIFS(Leads!$J$3:$J$502,Leads!$A$3:$A$502,">="&$B$38,Leads!$A$3:$A$502,"<"&EDATE($B$38,1),Leads!$D$3:$D$502,$A42,Leads!$M$3:$M$502,1)
A43: WEB-FA | B43: =COUNTIFS(Leads!$A$3:$A$502,">="&$B$38,Leads!$A$3:$A$502,"<"&EDATE($B$38,1),Leads!$D$3:$D$502,$A43) | C43: =COUNTIFS(Leads!$A$3:$A$502,">="&$B$38,Leads!$A$3:$A$502,"<"&EDATE($B$38,1),Leads!$D$3:$D$502,$A43,Leads!$M$3:$M$502,1) | D43: =IF(B43=0,"",C43/B43) | E43: =SUMIFS(Leads!$G$3:$G$502,Leads!$A$3:$A$502,">="&$B$38,Leads!$A$3:$A$502,"<"&EDATE($B$38,1),Leads!$D$3:$D$502,$A43,Leads!$M$3:$M$502,1) | F43: =SUMIFS(Leads!$J$3:$J$502,Leads!$A$3:$A$502,">="&$B$38,Leads!$A$3:$A$502,"<"&EDATE($B$38,1),Leads!$D$3:$D$502,$A43,Leads!$M$3:$M$502,1)
A44: WEB-GEN | B44: =COUNTIFS(Leads!$A$3:$A$502,">="&$B$38,Leads!$A$3:$A$502,"<"&EDATE($B$38,1),Leads!$D$3:$D$502,$A44) | C44: =COUNTIFS(Leads!$A$3:$A$502,">="&$B$38,Leads!$A$3:$A$502,"<"&EDATE($B$38,1),Leads!$D$3:$D$502,$A44,Leads!$M$3:$M$502,1) | D44: =IF(B44=0,"",C44/B44) | E44: =SUMIFS(Leads!$G$3:$G$502,Leads!$A$3:$A$502,">="&$B$38,Leads!$A$3:$A$502,"<"&EDATE($B$38,1),Leads!$D$3:$D$502,$A44,Leads!$M$3:$M$502,1) | F44: =SUMIFS(Leads!$J$3:$J$502,Leads!$A$3:$A$502,">="&$B$38,Leads!$A$3:$A$502,"<"&EDATE($B$38,1),Leads!$D$3:$D$502,$A44,Leads!$M$3:$M$502,1)
A45: GBP | B45: =COUNTIFS(Leads!$A$3:$A$502,">="&$B$38,Leads!$A$3:$A$502,"<"&EDATE($B$38,1),Leads!$D$3:$D$502,$A45) | C45: =COUNTIFS(Leads!$A$3:$A$502,">="&$B$38,Leads!$A$3:$A$502,"<"&EDATE($B$38,1),Leads!$D$3:$D$502,$A45,Leads!$M$3:$M$502,1) | D45: =IF(B45=0,"",C45/B45) | E45: =SUMIFS(Leads!$G$3:$G$502,Leads!$A$3:$A$502,">="&$B$38,Leads!$A$3:$A$502,"<"&EDATE($B$38,1),Leads!$D$3:$D$502,$A45,Leads!$M$3:$M$502,1) | F45: =SUMIFS(Leads!$J$3:$J$502,Leads!$A$3:$A$502,">="&$B$38,Leads!$A$3:$A$502,"<"&EDATE($B$38,1),Leads!$D$3:$D$502,$A45,Leads!$M$3:$M$502,1)
A46: ADS | B46: =COUNTIFS(Leads!$A$3:$A$502,">="&$B$38,Leads!$A$3:$A$502,"<"&EDATE($B$38,1),Leads!$D$3:$D$502,$A46) | C46: =COUNTIFS(Leads!$A$3:$A$502,">="&$B$38,Leads!$A$3:$A$502,"<"&EDATE($B$38,1),Leads!$D$3:$D$502,$A46,Leads!$M$3:$M$502,1) | D46: =IF(B46=0,"",C46/B46) | E46: =SUMIFS(Leads!$G$3:$G$502,Leads!$A$3:$A$502,">="&$B$38,Leads!$A$3:$A$502,"<"&EDATE($B$38,1),Leads!$D$3:$D$502,$A46,Leads!$M$3:$M$502,1) | F46: =SUMIFS(Leads!$J$3:$J$502,Leads!$A$3:$A$502,">="&$B$38,Leads!$A$3:$A$502,"<"&EDATE($B$38,1),Leads!$D$3:$D$502,$A46,Leads!$M$3:$M$502,1)
A47: All sources | B47: =SUM(B40:B46) | C47: =SUM(C40:C46) | D47: =IF(B47=0,"",C47/B47) | E47: =SUM(E40:E46) | F47: =SUM(F40:F46)
A49: By source code — all time
A50: Source | B50: Leads | C50: Won | D50: Conversion % | E50: Revenue | F50: Commission Owed
A51: WEB-GC | B51: =COUNTIFS(Leads!$D$3:$D$502,$A51) | C51: =COUNTIFS(Leads!$D$3:$D$502,$A51,Leads!$M$3:$M$502,1) | D51: =IF(B51=0,"",C51/B51) | E51: =SUMIFS(Leads!$G$3:$G$502,Leads!$D$3:$D$502,$A51,Leads!$M$3:$M$502,1) | F51: =SUMIFS(Leads!$J$3:$J$502,Leads!$D$3:$D$502,$A51,Leads!$M$3:$M$502,1)
A52: WEB-OSHC | B52: =COUNTIFS(Leads!$D$3:$D$502,$A52) | C52: =COUNTIFS(Leads!$D$3:$D$502,$A52,Leads!$M$3:$M$502,1) | D52: =IF(B52=0,"",C52/B52) | E52: =SUMIFS(Leads!$G$3:$G$502,Leads!$D$3:$D$502,$A52,Leads!$M$3:$M$502,1) | F52: =SUMIFS(Leads!$J$3:$J$502,Leads!$D$3:$D$502,$A52,Leads!$M$3:$M$502,1)
A53: WEB-HRD | B53: =COUNTIFS(Leads!$D$3:$D$502,$A53) | C53: =COUNTIFS(Leads!$D$3:$D$502,$A53,Leads!$M$3:$M$502,1) | D53: =IF(B53=0,"",C53/B53) | E53: =SUMIFS(Leads!$G$3:$G$502,Leads!$D$3:$D$502,$A53,Leads!$M$3:$M$502,1) | F53: =SUMIFS(Leads!$J$3:$J$502,Leads!$D$3:$D$502,$A53,Leads!$M$3:$M$502,1)
A54: WEB-FA | B54: =COUNTIFS(Leads!$D$3:$D$502,$A54) | C54: =COUNTIFS(Leads!$D$3:$D$502,$A54,Leads!$M$3:$M$502,1) | D54: =IF(B54=0,"",C54/B54) | E54: =SUMIFS(Leads!$G$3:$G$502,Leads!$D$3:$D$502,$A54,Leads!$M$3:$M$502,1) | F54: =SUMIFS(Leads!$J$3:$J$502,Leads!$D$3:$D$502,$A54,Leads!$M$3:$M$502,1)
A55: WEB-GEN | B55: =COUNTIFS(Leads!$D$3:$D$502,$A55) | C55: =COUNTIFS(Leads!$D$3:$D$502,$A55,Leads!$M$3:$M$502,1) | D55: =IF(B55=0,"",C55/B55) | E55: =SUMIFS(Leads!$G$3:$G$502,Leads!$D$3:$D$502,$A55,Leads!$M$3:$M$502,1) | F55: =SUMIFS(Leads!$J$3:$J$502,Leads!$D$3:$D$502,$A55,Leads!$M$3:$M$502,1)
...

Sheet Lists
A1: Source Codes | B1: Channels | C1: Statuses
A2: WEB-GC | B2: WhatsApp | C2: new
A3: WEB-OSHC | B3: Form | C3: quoted
A4: WEB-HRD | B4: Phone | C4: confirmed
A5: WEB-FA | B5: Google profile | C5: delivered
A6: WEB-GEN | C6: invoiced
A7: GBP | C7: paid
A8: ADS | C8: lost
A11: HOW TO USE (from your phone)
A12: 1. One row per lead on the Leads tab — fill the white columns only.
A13: 2. Source Code, Channel and Status are dropdowns — tap the cell to pick.
A14: 3. Deal Value (update to actual on invoice): type the number only (e.g. 1500), no currency symbol.
A15: 4. Commission Due = 15% of Deal Value, calculated automatically. Update Deal Value to the invoiced amount when the deal closes.
A16: 5. When the client pays you, enter the amount in Commission Paid.
A17: 6. Grey columns calculate automatically — do not type in them.
A18: 7. An amber row means the lead has been sitting at 'quoted' over 14 days — follow it up.
A19: 8. Monthly Rollup tab: set the Start month and Report month once; everything else updates itself.
A20: 9. 'Won' = status delivered, invoiced or paid. Conversion = won ÷ leads received.
A21: 10. Delete the 5 SAMPLE rows on the Leads tab when you start entering real leads.
